Traceback (most recent call last):
  File "/Library/Frameworks/Python.framework/Versions/3.12/lib/python3.12/site-packages/jupyter_cache/executors/utils.py", line 58, in single_nb_execution
    executenb(
  File "/Library/Frameworks/Python.framework/Versions/3.12/lib/python3.12/site-packages/nbclient/client.py", line 1319, in execute
    return NotebookClient(nb=nb, resources=resources, km=km, **kwargs).execute()
           ^^^^^^^^^^^^^^^^^^^^^^^^^^^^^^^^^^^^^^^^^^^^^^^^^^^^^^^^^^^^^^^^^^^^^
  File "/Library/Frameworks/Python.framework/Versions/3.12/lib/python3.12/site-packages/jupyter_core/utils/__init__.py", line 165, in wrapped
    return loop.run_until_complete(inner)
           ^^^^^^^^^^^^^^^^^^^^^^^^^^^^^^
  File "/Library/Frameworks/Python.framework/Versions/3.12/lib/python3.12/asyncio/base_events.py", line 686, in run_until_complete
    return future.result()
           ^^^^^^^^^^^^^^^
  File "/Library/Frameworks/Python.framework/Versions/3.12/lib/python3.12/site-packages/nbclient/client.py", line 709, in async_execute
    await self.async_execute_cell(
  File "/Library/Frameworks/Python.framework/Versions/3.12/lib/python3.12/site-packages/nbclient/client.py", line 1062, in async_execute_cell
    await self._check_raise_for_error(cell, cell_index, exec_reply)
  File "/Library/Frameworks/Python.framework/Versions/3.12/lib/python3.12/site-packages/nbclient/client.py", line 918, in _check_raise_for_error
    raise CellExecutionError.from_cell_and_msg(cell, exec_reply_content)
nbclient.exceptions.CellExecutionError: An error occurred while executing the following cell:
------------------
from myst_nb import glue
import numpy as np
import matplotlib.pyplot as plt
f,ax = plt.subplots()
ax.set_xlim([-0.5,3.1])
ax.set_ylim([-0.5,2.1])
ax.set_axis_off()
V = [3,2]
ax.quiver(0, 0, V[0], V[1], angles='xy', scale_units='xy', scale=1, color='r')
ax.quiver(3, 0, 0, V[1], angles='xy', scale_units='xy', scale=1, color='b', width=0.001)
ax.quiver(0, 0, V[0], 0, angles='xy', scale_units='xy', scale=1, color='b',width=0.001)
ax.annotate("$x_2$",(3,1),horizontalalignment='left')
ax.annotate("$x_1$",(1.5,0),verticalalignment='top')

glue("geom_vector", f, display=False)
------------------


[0;31m---------------------------------------------------------------------------[0m
[0;31mModuleNotFoundError[0m                       Traceback (most recent call last)
Cell [0;32mIn[1], line 3[0m
[1;32m      1[0m [38;5;28;01mfrom[39;00m [38;5;21;01mmyst_nb[39;00m [38;5;28;01mimport[39;00m glue
[1;32m      2[0m [38;5;28;01mimport[39;00m [38;5;21;01mnumpy[39;00m [38;5;28;01mas[39;00m [38;5;21;01mnp[39;00m
[0;32m----> 3[0m [38;5;28;01mimport[39;00m [38;5;21;01mmatplotlib[39;00m[38;5;21;01m.[39;00m[38;5;21;01mpyplot[39;00m [38;5;28;01mas[39;00m [38;5;21;01mplt[39;00m
[1;32m      4[0m f,ax [38;5;241m=[39m plt[38;5;241m.[39msubplots()
[1;32m      5[0m ax[38;5;241m.[39mset_xlim([[38;5;241m-[39m[38;5;241m0.5[39m,[38;5;241m3.1[39m])

[0;31mModuleNotFoundError[0m: No module named 'matplotlib'

