Traceback (most recent call last):
  File "/Library/Frameworks/Python.framework/Versions/3.10/lib/python3.10/site-packages/jupyter_cache/executors/utils.py", line 58, in single_nb_execution
    executenb(
  File "/Library/Frameworks/Python.framework/Versions/3.10/lib/python3.10/site-packages/nbclient/client.py", line 1305, in execute
    return NotebookClient(nb=nb, resources=resources, km=km, **kwargs).execute()
  File "/Library/Frameworks/Python.framework/Versions/3.10/lib/python3.10/site-packages/jupyter_core/utils/__init__.py", line 168, in wrapped
    return loop.run_until_complete(inner)
  File "/Library/Frameworks/Python.framework/Versions/3.10/lib/python3.10/asyncio/base_events.py", line 641, in run_until_complete
    return future.result()
  File "/Library/Frameworks/Python.framework/Versions/3.10/lib/python3.10/site-packages/nbclient/client.py", line 705, in async_execute
    await self.async_execute_cell(
  File "/Library/Frameworks/Python.framework/Versions/3.10/lib/python3.10/site-packages/nbclient/client.py", line 1058, in async_execute_cell
    await self._check_raise_for_error(cell, cell_index, exec_reply)
  File "/Library/Frameworks/Python.framework/Versions/3.10/lib/python3.10/site-packages/nbclient/client.py", line 914, in _check_raise_for_error
    raise CellExecutionError.from_cell_and_msg(cell, exec_reply_content)
nbclient.exceptions.CellExecutionError: An error occurred while executing the following cell:
------------------
#Matching terms with their scores for 3rd topic
scored_terms = zip(U[:,3], idx2word)

#Max k terms for topic 3
k = 5
for score,term in  sorted(scored_terms,reverse=True):
   print(f'{term} : {score}')

#Matching terms with their scores for the 9th topic
scored_terms = zip(U[:,9], idx2word)
k = 5
for score,term in  sorted(scored_terms,reverse=True):
   print(f'{term} : {score}'
------------------


[0;36m  Cell [0;32mIn[9], line 13[0;36m[0m
[0;31m    print(f'{term} : {score}'[0m
[0m         ^[0m
[0;31mSyntaxError[0m[0;31m:[0m '(' was never closed


