Traceback (most recent call last):
  File "/Library/Frameworks/Python.framework/Versions/3.10/lib/python3.10/site-packages/jupyter_cache/executors/utils.py", line 58, in single_nb_execution
    executenb(
  File "/Library/Frameworks/Python.framework/Versions/3.10/lib/python3.10/site-packages/nbclient/client.py", line 1305, in execute
    return NotebookClient(nb=nb, resources=resources, km=km, **kwargs).execute()
  File "/Library/Frameworks/Python.framework/Versions/3.10/lib/python3.10/site-packages/jupyter_core/utils/__init__.py", line 168, in wrapped
    return loop.run_until_complete(inner)
  File "/Library/Frameworks/Python.framework/Versions/3.10/lib/python3.10/asyncio/base_events.py", line 641, in run_until_complete
    return future.result()
  File "/Library/Frameworks/Python.framework/Versions/3.10/lib/python3.10/site-packages/nbclient/client.py", line 705, in async_execute
    await self.async_execute_cell(
  File "/Library/Frameworks/Python.framework/Versions/3.10/lib/python3.10/site-packages/nbclient/client.py", line 1058, in async_execute_cell
    await self._check_raise_for_error(cell, cell_index, exec_reply)
  File "/Library/Frameworks/Python.framework/Versions/3.10/lib/python3.10/site-packages/nbclient/client.py", line 914, in _check_raise_for_error
    raise CellExecutionError.from_cell_and_msg(cell, exec_reply_content)
nbclient.exceptions.CellExecutionError: An error occurred while executing the following cell:
------------------
%matplotlib inline

import matplotlib.pyplot as plt

def similarity_matrix(datalist):
    N     = len(datalist)
    S     = np.empty((N,N))
    
    for idx,x_entry in enumerate(datalist):
        for jdx,y_entry in enumerate(datalist):
            x_key,x_value  = x_entry
            y_key,y_value  = y_entry
            S[idx,jdx] = similarity(x_key,y_key)

    words = [value for (key,value) in datalist] 

            
    fig, ax = plt.subplots()
    im = ax.imshow(S)
    fig.colorbar(im, ax=ax)
    ax.set_xticks(np.arange(N))
    ax.set_yticks(np.arange(N))
    ax.set_xticklabels(words,rotation = 45)
    ax.set_yticklabels(words)
    
    plt.show()

    
similarity_matrix(database)    
------------------


[0;31m---------------------------------------------------------------------------[0m
[0;31mNameError[0m                                 Traceback (most recent call last)
Cell [0;32mIn[4], line 29[0m
[1;32m     24[0m     ax[38;5;241m.[39mset_yticklabels(words)
[1;32m     26[0m     plt[38;5;241m.[39mshow()
[0;32m---> 29[0m similarity_matrix([43mdatabase[49m)    

[0;31mNameError[0m: name 'database' is not defined

